Workbook
Name DENE: '[2]tahakkuk müzekkeresi_1'!#REF!
Name DENE: '[2]tahakkuk müzekkeresi_1'!#REF!
Name dflt2: [1]Sayfa1!$G$21
Name Öğrenci: 'Banka Lis.'!#REF!
Name Sözleşmeli: 'Banka Lis.'!#REF!

Sheet Puantaj
B1: BURSA ULUDAĞ ÜNİVERSİTESİ GENEL SEKRETERLİK ÖZEL KALEM 13376 PORTAL NOLU KAMPÜS 1 İŞKUR GENÇLİK PROGRAMI KATILIMCI GÜN ÇİZELGESİ | AN1: YIL | AO1: 2025
AN2: AY | AO2: Aralık
B3: KATILIMCI BİLGİLERİ | F3: =VLOOKUP($AO$2,$AQ$4:$AS$17,2,0) -> 45992 | G3: =IF(MONTH(F3)=MONTH(F3+1),F3+1,"") -> 45993 | H3: =IF(MONTH(G3)=MONTH(G3+1),G3+1,"") -> 45994 | I3: =IF(MONTH(H3)=MONTH(H3+1),H3+1,"") -> 45995 | J3: =IF(MONTH(I3)=MONTH(I3+1),I3+1,"") -> 45996 | K3: =IF(MONTH(J3)=MONTH(J3+1),J3+1,"") -> 45997 | L3: =IF(MONTH(K3)=MONTH(K3+1),K3+1,"") -> 45998 | M3: =IF(MONTH(L3)=MONTH(L3+1),L3+1,"") -> 45999 | N3: =IF(MONTH(M3)=MONTH(M3+1),M3+1,"") -> 46000 | ... AJ3: =IF(MONTH(AI3)=MONTH(AI3+1),AI3+1,"") -> 46022 | AK3: ÇALIŞTIĞI GÜNLER | AL3: RAPORLU VEYA GELİNMEYEN GÜNLER | AM3: YILLIK İZİN DURUMU İzin Takip İçindir (7 gün ) | AN3: Geldiği günler : X Eğitim günü:E Gelmediği Günler : T Raporlu Günler : R İzinli : İ
A4: IBAN | B4: SIRA | C4: TC | D4: AD SOYAD | AN4: İşe Giriş Tarihi | AO4: İşten Çıkışı Tarihi | AQ4: AYLAR | AR4: İLK GÜN | AS4: SON GÜN | AT4: =SUM(AK6:AK194) -> 2240
F5: =WEEKDAY(F3,2) -> 1 | G5: =WEEKDAY(G3,2) -> 2 | H5: =WEEKDAY(H3,2) -> 3 | I5: =WEEKDAY(I3,2) -> 4 | J5: =WEEKDAY(J3,2) -> 5 | K5: =WEEKDAY(K3,2) -> 6 | L5: =WEEKDAY(L3,2) -> 7 | M5: =WEEKDAY(M3,2) -> 1 | ... AJ5: =WEEKDAY(AJ3,2) -> 3
A6: TR290001002151713143585001 | B6: 1 | C6: 22985652920 | D6: ABDURRAHMAN CENGİZ | E6: AYDOĞDU | H6: X | I6: X | J6: X | O6: X | P6: X | Q6: X | V6: X | W6: X | X6: X | AC6: X | AD6: X | AE6: X | AJ6: X | AK6: =+COUNTIF(F6:AJ6,"X")+COUNTIF(F6:AJ6,"E") -> 13 | AL6: =+COUNTIF(F6:AJ6,"R")+COUNTIF(F6:AJ6,"T")+COUNTIF(F6:AJ6,"İ") -> 0 | AM6: =+COUNTIF(F6:AJ6,"İ") -> 0 | AN6: 45985 | AQ6: Ocak | AR6: 45658 | AS6: =EOMONTH(AR6,0) -> 45688 | AT6: =+COUNTIF(F6:AJ194,"X")+COUNTIF(F6:AJ193,"E") -> 2240
A7: TR270020500009943979400001 | B7: 2 | C7: 10264855810 | D7: AHMET EMİRHAN | E7: ELDEMİR | F7: X | H7: X | M7: X | T7: X | AA7: X | AH7: X | AK7: =+COUNTIF(F7:AJ7,"X")+COUNTIF(F7:AJ7,"E") -> 6 | AL7: =+COUNTIF(F7:AJ7,"R")+COUNTIF(F7:AJ7,"T")+COUNTIF(F7:AJ7,"İ") -> 0 | AM7: =+COUNTIF(F7:AJ7,"İ") -> 0 | AN7: 45985 | AQ7: Şubat | AR7: 45689 | AS7: =EOMONTH(AR7,0) -> 45716
A8: TR370001009010555427505003 | B8: 3 | C8: 11230293988 | D8: AHMET SAMED | E8: KARABULUT | H8: X | I8: X | J8: X | O8: X | P8: X | Q8: X | V8: X | W8: X | X8: X | AC8: X | AD8: X | AE8: X | AH8: X | AI8: X | AK8: =+COUNTIF(F8:AJ8,"X")+COUNTIF(F8:AJ8,"E") -> 14 | AL8: =+COUNTIF(F8:AJ8,"R")+COUNTIF(F8:AJ8,"T")+COUNTIF(F8:AJ8,"İ") -> 0 | AM8: =+COUNTIF(F8:AJ8,"İ") -> 0 | AN8: 45985 | AQ8: Mart | AR8: 45717 | AS8: =EOMONTH(AR8,0) -> 45747
A9: TR550006701000000037357882 | B9: 4 | C9: 10271762804 | D9: AHMET | E9: ŞEN | H9: X | J9: X | K9: X | O9: X | Q9: X | R9: X | V9: X | X9: X | Y9: X | AC9: X | AE9: X | AF9: X | AJ9: X | AK9: =+COUNTIF(F9:AJ9,"X")+COUNTIF(F9:AJ9,"E") -> 13 | AL9: =+COUNTIF(F9:AJ9,"R")+COUNTIF(F9:AJ9,"T")+COUNTIF(F9:AJ9,"İ") -> 0 | AM9: =+COUNTIF(F9:AJ9,"İ") -> 0 | AN9: 45985 | AQ9: Nisan | AR9: 45748 | AS9: =EOMONTH(AR9,0) -> 45777
A10: TR040001009010348991905001 | B10: 5 | C10: 10067475932 | D10: AHMET YASİN | E10: KURT | F10: X | I10: X | J10: X | M10: X | P10: X | Q10: X | T10: X | W10: X | X10: X | AA10: X | AD10: X | AE10: X | AH10: X | AI10: X | AK10: =+COUNTIF(F10:AJ10,"X")+COUNTIF(F10:AJ10,"E") -> 14 | AL10: =+COUNTIF(F10:AJ10,"R")+COUNTIF(F10:AJ10,"T")+COUNTIF(F10:AJ10,"İ") -> 0 | AM10: =+COUNTIF(F10:AJ10,"İ") -> 0 | AN10: 45985 | AQ10: Mayıs | AR10: 45778 | AS10: =EOMONTH(AR10,0) -> 45808
A11: TR070001009010961041905002 | B11: 6 | C11: 13333175444 | D11: AKİF YAVUZ | E11: ZENGİN | F11: X | M11: R | T11: X | AA11: X | AH11: X | AK11: =+COUNTIF(F11:AJ11,"X")+COUNTIF(F11:AJ11,"E") -> 4 | AL11: =+COUNTIF(F11:AJ11,"R")+COUNTIF(F11:AJ11,"T")+COUNTIF(F11:AJ11,"İ") -> 1 | AM11: =+COUNTIF(F11:AJ11,"İ") -> 0 | AN11: 45985 | AQ11: Haziran | AR11: 45809 | AS11: =EOMONTH(AR11,0) -> 45838
A12: TR250001009010259614605003 | B12: 7 | C12: 34411910856 | D12: ALEYNA | E12: ÇAKAR | AK12: =+COUNTIF(F12:AJ12,"X")+COUNTIF(F12:AJ12,"E") -> 0 | AL12: =+COUNTIF(F12:AJ12,"R")+COUNTIF(F12:AJ12,"T")+COUNTIF(F12:AJ12,"İ") -> 0 | AM12: =+COUNTIF(F12:AJ12,"İ") -> 0 | AN12: 45985 | AO12: 46022 | AQ12: Temmuz | AR12: 45839 | AS12: =EOMONTH(AR12,0) -> 45869
A13: TR580001009010556440305002 | B13: 8 | C13: 11069535280 | D13: ALİGAFFAR | E13: AYDIN | J13: X | K13: X | L13: X | Q13: X | R13: X | S13: X | X13: X | Y13: X | Z13: X | AE13: X | AF13: X | AG13: X | AK13: =+COUNTIF(F13:AJ13,"X")+COUNTIF(F13:AJ13,"E") -> 12 | AL13: =+COUNTIF(F13:AJ13,"R")+COUNTIF(F13:AJ13,"T")+COUNTIF(F13:AJ13,"İ") -> 0 | AM13: =+COUNTIF(F13:AJ13,"İ") -> 0 | AN13: 45985 | AQ13: Ağustos | AR13: 45870 | AS13: =EOMONTH(AR13,0) -> 45900
A14: TR960001200122900001249734 | B14: 9 | C14: 10420954296 | D14: ARİF | E14: TURAN | G14: X | H14: X | J14: X | N14: X | O14: X | Q14: X | U14: X | V14: X | X14: X | AB14: X | AC14: X | AE14: X | AI14: X | AJ14: X | AK14: =+COUNTIF(F14:AJ14,"X")+COUNTIF(F14:AJ14,"E") -> 14 | AL14: =+COUNTIF(F14:AJ14,"R")+COUNTIF(F14:AJ14,"T")+COUNTIF(F14:AJ14,"İ") -> 0 | AM14: =+COUNTIF(F14:AJ14,"İ") -> 0 | AN14: 45985 | AQ14: Eylül | AR14: 45901 | AS14: =EOMONTH(AR14,0) -> 45930
A15: TR530004600007888000653780 | B15: 10 | C15: 11039638348 | D15: ASLAN ERAY | E15: KARAVAŞ | H15: X | I15: X | J15: X | M15: X | P15: X | Q15: X | T15: X | U15: X | V15: X | AB15: X | AC15: X | AD15: X | AH15: X | AI15: X | AJ15: X | AK15: =+COUNTIF(F15:AJ15,"X")+COUNTIF(F15:AJ15,"E") -> 15 | AL15: =+COUNTIF(F15:AJ15,"R")+COUNTIF(F15:AJ15,"T")+COUNTIF(F15:AJ15,"İ") -> 0 | AM15: =+COUNTIF(F15:AJ15,"İ") -> 0 | AN15: 45985 | AQ15: Ekim | AR15: 45931 | AS15: =EOMONTH(AR15,0) -> 45961
A16: TR070001009010550885705001 | B16: 11 | C16: 18397728780 | D16: ASLI | E16: BEKTAŞ | J16: X | Q16: X | X16: X | AE16: X | AJ16: X | AK16: =+COUNTIF(F16:AJ16,"X")+COUNTIF(F16:AJ16,"E") -> 5 | AL16: =+COUNTIF(F16:AJ16,"R")+COUNTIF(F16:AJ16,"T")+COUNTIF(F16:AJ16,"İ") -> 0 | AM16: =+COUNTIF(F16:AJ16,"İ") -> 0 | AN16: 45985 | AQ16: Kasım | AR16: 45962 | AS16: =EOMONTH(AR16,0) -> 45991
A17: TR080001001914961839085005 | B17: 12 | C17: 31885265086 | D17: AYBERK | E17: EREN | F17: X | I17: X | J17: X | M17: X | P17: X | Q17: X | T17: X | W17: X | X17: X | AA17: X | AD17: X | AE17: X | AK17: =+COUNTIF(F17:AJ17,"X")+COUNTIF(F17:AJ17,"E") -> 12 | AL17: =+COUNTIF(F17:AJ17,"R")+COUNTIF(F17:AJ17,"T")+COUNTIF(F17:AJ17,"İ") -> 0 | AM17: =+COUNTIF(F17:AJ17,"İ") -> 0 | AN17: 45985 | AQ17: Aralık | AR17: 45992 | AS17: =EOMONTH(AR17,0) -> 46022
A18: TR860004600563888000416642 | B18: 13 | C18: 16364821786 | D18: AYBERK | E18: KILIÇ | F18: X | K18: X | L18: X | M18: X | R18: X | S18: X | T18: X | Y18: X | Z18: X | AA18: X | AF18: X | AG18: X | AH18: X | AK18: =+COUNTIF(F18:AJ18,"X")+COUNTIF(F18:AJ18,"E") -> 13 | AL18: =+COUNTIF(F18:AJ18,"R")+COUNTIF(F18:AJ18,"T")+COUNTIF(F18:AJ18,"İ") -> 0 | AM18: =+COUNTIF(F18:AJ18,"İ") -> 0 | AN18: 45985
A19: TR520001009010110010105001 | B19: 14 | C19: 10307955460 | D19: AYÇA | E19: YAZICI | F19: X | H19: X | J19: X | M19: X | O19: X | Q19: X | T19: X | V19: X | X19: X | AA19: X | AC19: X | AE19: İ | AH19: X | AJ19: X | AK19: =+COUNTIF(F19:AJ19,"X")+COUNTIF(F19:AJ19,"E") -> 13 | AL19: =+COUNTIF(F19:AJ19,"R")+COUNTIF(F19:AJ19,"T")+COUNTIF(F19:AJ19,"İ") -> 1 | AM19: =+COUNTIF(F19:AJ19,"İ") -> 1 | AN19: 45985
A20: TR830001009010018214505001 | B20: 15 | C20: 37796134572 | D20: AYŞE | E20: KADIOĞULLARI | F20: X | G20: X | H20: X | M20: X | N20: X | O20: X | T20: X | U20: X | V20: X | AA20: X | AB20: X | AC20: X | AH20: İ | AI20: İ | AJ20: X | AK20: =+COUNTIF(F20:AJ20,"X")+COUNTIF(F20:AJ20,"E") -> 13 | AL20: =+COUNTIF(F20:AJ20,"R")+COUNTIF(F20:AJ20,"T")+COUNTIF(F20:AJ20,"İ") -> 2 | AM20: =+COUNTIF(F20:AJ20,"İ") -> 2 | AN20: 45985
A21: TR340006701000000012356801 | B21: 16 | C21: 20425647000 | D21: AYŞE | E21: KÜÇÜKALİ | H21: X | I21: X | J21: X | O21: X | P21: X | Q21: X | V21: X | W21: X | X21: X | AC21: X | AD21: X | AE21: X | AK21: =+COUNTIF(F21:AJ21,"X")+COUNTIF(F21:AJ21,"E") -> 12 | AL21: =+COUNTIF(F21:AJ21,"R")+COUNTIF(F21:AJ21,"T")+COUNTIF(F21:AJ21,"İ") -> 0 | AM21: =+COUNTIF(F21:AJ21,"İ") -> 0 | AN21: 45985
A22: TR650001009010552580105001 | B22: 17 | C22: 10211811296 | D22: AYŞE NUR | E22: TÜRKYILMAZ | G22: X | H22: X | J22: X | N22: X | O22: X | Q22: X | U22: X | V22: X | X22: X | AB22: X | AC22: X | AE22: X | AI22: X | AJ22: X | AK22: =+COUNTIF(F22:AJ22,"X")+COUNTIF(F22:AJ22,"E") -> 14 | AL22: =+COUNTIF(F22:AJ22,"R")+COUNTIF(F22:AJ22,"T")+COUNTIF(F22:AJ22,"İ") -> 0 | AM22: =+COUNTIF(F22:AJ22,"İ") -> 0 | AN22: 45985
A23: TR560001009010276446500001 | B23: 18 | C23: 38158642018 | D23: AYŞENUR TUĞBA | E23: KILIÇARSLAN | H23: X | I23: X | J23: X | O23: X | P23: X | Q23: X | V23: X | W23: X | X23: X | AC23: X | AD23: X | AE23: X | AJ23: X | AK23: =+COUNTIF(F23:AJ23,"X")+COUNTIF(F23:AJ23,"E") -> 13 | AL23: =+COUNTIF(F23:AJ23,"R")+COUNTIF(F23:AJ23,"T")+COUNTIF(F23:AJ23,"İ") -> 0 | AM23: =+COUNTIF(F23:AJ23,"İ") -> 0 | AN23: 45985
A24: TR310004601245888000103590 | B24: 19 | C24: 10391956060 | D24: AYŞENUR | E24: YILDIRIM | F24: X | G24: X | I24: X | M24: X | N24: X | P24: X | T24: X | U24: X | W24: X | AA24: X | AB24: X | AD24: X | AH24: X | AI24: X | AK24: =+COUNTIF(F24:AJ24,"X")+COUNTIF(F24:AJ24,"E") -> 14 | AL24: =+COUNTIF(F24:AJ24,"R")+COUNTIF(F24:AJ24,"T")+COUNTIF(F24:AJ24,"İ") -> 0 | AM24: =+COUNTIF(F24:AJ24,"İ") -> 0 | AN24: 45985
A25: TR860001009010458311205001 | B25: 20 | C25: 10075858284 | D25: AZİZE NUR | E25: TUTUM | G25: X | J25: X | N25: İ | Q25: X | T25: X | U25: X | V25: X | AB25: İ | AE25: X | AI25: İ | AK25: =+COUNTIF(F25:AJ25,"X")+COUNTIF(F25:AJ25,"E") -> 7 | AL25: =+COUNTIF(F25:AJ25,"R")+COUNTIF(F25:AJ25,"T")+COUNTIF(F25:AJ25,"İ") -> 3 | AM25: =+COUNTIF(F25:AJ25,"İ") -> 3 | AN25: 45985
A26: TR800006200068700006892740 | B26: 21 | C26: 38815458440 | D26: AZRA | E26: ÖZGÜL | F26: X | G26: X | J26: X | M26: X | N26: X | Q26: X | T26: X | U26: X | X26: X | AA26: X | AB26: X | AE26: X | AH26: X | AI26: X | AK26: =+COUNTIF(F26:AJ26,"X")+COUNTIF(F26:AJ26,"E") -> 14 | AL26: =+COUNTIF(F26:AJ26,"R")+COUNTIF(F26:AJ26,"T")+COUNTIF(F26:AJ26,"İ") -> 0 | AM26: =+COUNTIF(F26:AJ26,"İ") -> 0 | AN26: 45985
A27: TR260006701000000078559930 | B27: 22 | C27: 22682146630 | D27: BEGÜM | E27: YALÇIN | F27: X | G27: X | J27: X | M27: X | N27: X | Q27: İ | T27: X | U27: X | X27: X | AA27: X | AB27: X | AE27: X | AH27: X | AI27: X | AK27: =+COUNTIF(F27:AJ27,"X")+COUNTIF(F27:AJ27,"E") -> 13 | AL27: =+COUNTIF(F27:AJ27,"R")+COUNTIF(F27:AJ27,"T")+COUNTIF(F27:AJ27,"İ") -> 1 | AM27: =+COUNTIF(F27:AJ27,"İ") -> 1 | AN27: 45985
A28: TR780004600563888000363339 | B28: 23 | C28: 10048324686 | D28: BERAT | E28: ÇAM | G28: X | H28: X | I28: X | N28: X | O28: X | P28: X | U28: X | V28: X | W28: X | AB28: X | AC28: X | AD28: X | AK28: =+COUNTIF(F28:AJ28,"X")+COUNTIF(F28:AJ28,"E") -> 12 | AL28: =+COUNTIF(F28:AJ28,"R")+COUNTIF(F28:AJ28,"T")+COUNTIF(F28:AJ28,"İ") -> 0 | AM28: =+COUNTIF(F28:AJ28,"İ") -> 0 | AN28: 45985
A29: TR830001009010204648505001 | B29: 24 | C29: 60583295750 | D29: BETÜL | E29: ÖZTÜRK | H29: X | J29: X | K29: X | O29: X | Q29: X | R29: X | V29: X | X29: X | Y29: X | AC29: X | AE29: X | AF29: X | AJ29: X | AK29: =+COUNTIF(F29:AJ29,"X")+COUNTIF(F29:AJ29,"E") -> 13 | AL29: =+COUNTIF(F29:AJ29,"R")+COUNTIF(F29:AJ29,"T")+COUNTIF(F29:AJ29,"İ") -> 0 | AM29: =+COUNTIF(F29:AJ29,"İ") -> 0 | AN29: 45985
A30: TR350006200151700006611592 | B30: 25 | C30: 15829750838 | D30: BETÜL | E30: UYAR | H30: X | J30: X | O30: X | Q30: X | U30: X | V30: X | X30: X | AB30: X | AC30: X | AE30: X | AI30: X | AJ30: X | AK30: =+COUNTIF(F30:AJ30,"X")+COUNTIF(F30:AJ30,"E") -> 12 | AL30: =+COUNTIF(F30:AJ30,"R")+COUNTIF(F30:AJ30,"T")+COUNTIF(F30:AJ30,"İ") -> 0 | AM30: =+COUNTIF(F30:AJ30,"İ") -> 0 | AN30: 45985
A31: TR390001009010263272305001 | B31: 27 | C31: 12029296494 | D31: BİLAL EMİR | E31: GÖK | F31: X | G31: X | H31: X | M31: X | N31: X | O31: X | V31: X | W31: X | X31: X | AC31: X | AD31: X | AE31: X | AH31: X | AI31: X | AJ31: X | AK31: =+COUNTIF(F31:AJ31,"X")+COUNTIF(F31:AJ31,"E") -> 15 | AL31: =+COUNTIF(F31:AJ31,"R")+COUNTIF(F31:AJ31,"T")+COUNTIF(F31:AJ31,"İ") -> 0 | AM31: =+COUNTIF(F31:AJ31,"İ") -> 0 | AN31: 45985
A32: TR930006400000180300609819 | B32: 26 | C32: 11559114636 | D32: BİLAL | E32: GÜNGÖR | G32: X | Q32: İ | Z32: İ | AG32: İ | AK32: =+COUNTIF(F32:AJ32,"X")+COUNTIF(F32:AJ32,"E") -> 1 | AL32: =+COUNTIF(F32:AJ32,"R")+COUNTIF(F32:AJ32,"T")+COUNTIF(F32:AJ32,"İ") -> 3 | AM32: =+COUNTIF(F32:AJ32,"İ") -> 3 | AN32: 45985
A33: TR860001001799959944335001 | B33: 28 | C33: 16765732636 | D33: BUSE | E33: ALACA | F33: X | G33: X | I33: X | M33: X | N33: X | P33: X | T33: X | U33: X | W33: X | AA33: X | AB33: X | AD33: X | AH33: X | AI33: X | AK33: =+COUNTIF(F33:AJ33,"X")+COUNTIF(F33:AJ33,"E") -> 14 | AL33: =+COUNTIF(F33:AJ33,"R")+COUNTIF(F33:AJ33,"T")+COUNTIF(F33:AJ33,"İ") -> 0 | AM33: =+COUNTIF(F33:AJ33,"İ") -> 0 | AN33: 45985
A34: TR480004600094888000220489 | B34: 29 | C34: 10169157156 | D34: BUSE | E34: PAMUK | F34: X | M34: X | T34: X | AA34: X | AK34: =+COUNTIF(F34:AJ34,"X")+COUNTIF(F34:AJ34,"E") -> 4 | AL34: =+COUNTIF(F34:AJ34,"R")+COUNTIF(F34:AJ34,"T")+COUNTIF(F34:AJ34,"İ") -> 0 | AM34: =+COUNTIF(F34:AJ34,"İ") -> 0 | AN34: 45985 | AO34: 46022
A35: TR350001009010260552505001 | B35: 30 | C35: 22309168236 | D35: CAFER | E35: SOYLU | F35: X | G35: X | J35: X | M35: X | N35: X | Q35: X | T35: X | U35: X | X35: X | AA35: X | AB35: X | AE35: X | AH35: X | AI35: X | AK35: =+COUNTIF(F35:AJ35,"X")+COUNTIF(F35:AJ35,"E") -> 14 | AL35: =+COUNTIF(F35:AJ35,"R")+COUNTIF(F35:AJ35,"T")+COUNTIF(F35:AJ35,"İ") -> 0 | AM35: =+COUNTIF(F35:AJ35,"İ") -> 0 | AN35: 45985
A36: TR290001009010067788405001 | B36: 31 | C36: 15725667650 | D36: CANER | E36: YILDIZ | F36: X | K36: X | L36: X | M36: X | R36: X | S36: X | T36: X | Y36: X | Z36: X | AA36: X | AC36: X | AG36: X | AH36: X | AJ36: X | AK36: =+COUNTIF(F36:AJ36,"X")+COUNTIF(F36:AJ36,"E") -> 14 | AL36: =+COUNTIF(F36:AJ36,"R")+COUNTIF(F36:AJ36,"T")+COUNTIF(F36:AJ36,"İ") -> 0 | AM36: =+COUNTIF(F36:AJ36,"İ") -> 0 | AN36: 45985
A37: TR750001200929900001140213 | B37: 32 | C37: 15709804262 | D37: CEMAL AFŞİN | E37: TÜRKYILMAZ | G37: X | H37: X | J37: X | N37: X | Q37: X | U37: X | V37: X | X37: X | AB37: X | AE37: X | AI37: X | AJ37: X | AK37: =+COUNTIF(F37:AJ37,"X")+COUNTIF(F37:AJ37,"E") -> 12 | AL37: =+COUNTIF(F37:AJ37,"R")+COUNTIF(F37:AJ37,"T")+COUNTIF(F37:AJ37,"İ") -> 0 | AM37: =+COUNTIF(F37:AJ37,"İ") -> 0 | AN37: 45985
A38: TR220006701000000033603703 | B38: 33 | C38: 10841685564 | D38: CEMRE | E38: GÜRŞEN | G38: X | H38: X | I38: X | N38: X | O38: X | P38: X | U38: X | V38: X | W38: X | AB38: X | AC38: X | AD38: X | AI38: X | AJ38: X | AK38: =+COUNTIF(F38:AJ38,"X")+COUNTIF(F38:AJ38,"E") -> 14 | AL38: =+COUNTIF(F38:AJ38,"R")+COUNTIF(F38:AJ38,"T")+COUNTIF(F38:AJ38,"İ") -> 0 | AM38: =+COUNTIF(F38:AJ38,"İ") -> 0 | AN38: 45985
A39: TR740001009010956764805002 | B39: 34 | C39: 11102488016 | D39: CEREN | E39: YILDIRIM | F39: X | J39: X | K39: X | M39: X | Q39: X | R39: X | T39: X | X39: X | Y39: X | AA39: X | AE39: X | AF39: X | AH39: X | AK39: =+COUNTIF(F39:AJ39,"X")+COUNTIF(F39:AJ39,"E") -> 13 | AL39: =+COUNTIF(F39:AJ39,"R")+COUNTIF(F39:AJ39,"T")+COUNTIF(F39:AJ39,"İ") -> 0 | AM39: =+COUNTIF(F39:AJ39,"İ") -> 0 | AN39: 45985
A40: TR450006701000000075954168 | B40: 35 | C40: 45631014194 | D40: ÇAĞLAYAN EFE | E40: KOYUNCU | I40: X | K40: X | L40: X | P40: X | R40: X | S40: X | W40: X | Y40: X | Z40: X | AD40: X | AF40: X | AG40: X | AK40: =+COUNTIF(F40:AJ40,"X")+COUNTIF(F40:AJ40,"E") -> 12 | AL40: =+COUNTIF(F40:AJ40,"R")+COUNTIF(F40:AJ40,"T")+COUNTIF(F40:AJ40,"İ") -> 0 | AM40: =+COUNTIF(F40:AJ40,"İ") -> 0 | AN40: 45985
...

Sheet BORDRO
A2: BURSA ULUDAĞ ÜNİVERSİTESİ GENEL SEKRETERLİK ÖZEL KALEM 13376 PORTAL NOLU KAMPÜS 1 İŞKUR GENÇLİK PROGRAMI ÖDEME BORDROSU | Q2: Dönemi : 01.12.2025- 31.12.2025
A3: S.N. | B3: T.C. KİMLİK NUMARASI | C3: ADI | D3: SOYADI | E3: GÖREV YERİ | F3: AYLIK TOPLAM ÇALIŞILAN GÜN SAYISI | G3: İŞKUR GENÇLİK PROG CEP HARÇLIĞI TUTARI | H3: Sosyal Güvenlik Primi Devlet Ödemesi (%5,5) | I3: Tahakkuk Toplamı | J3: KESİNTİLER | T3: Ödenmesi Gereken Net Tutar
J4: GELİR VERGİSİ İSTİSNA UYGULAMA | N4: DAMGA VERGİSİ İSTİSNA UYGULAMA | Q4: Genel Sağ.Sig.Prm Dev.%4,5 + Kısa Vad.Sig.K Dev.%1 Toplam= %5,5 | R4: İcra Kesintisi | S4: Toplam Kesinti (SGK kesintisi ve Varsa Diğer)
J5: Gelir Vergisi Matrahı | K5: Hesaplanan Gelir Vergisi | L5: GV İstisna Tutarı | M5: Gelir Vergisi Kesintisi | N5: Hesaplanan Damga Vergisi | O5: DV İstisna Tutarı | P5: Damga Vergisi Kesintisi
A6: =+'Banka Lis.'!B5 -> 1 | B6: =+Puantaj!C6 -> 22985652920 | C6: =+Puantaj!D6 -> ABDURRAHMAN CENGİZ | D6: =+Puantaj!E6 -> AYDOĞDU | E6: =+'Banka Lis.'!H5 -> Bursa UludağÜniversitesi Üniveristesi Genel Sekreterlik Özel Kalem | F6: =+Puantaj!AK6 -> 13 | G6: =F6*1083 -> 14079 | H6: =G6*0.055 -> 774.345 | I6: =G6+H6 -> 14853.345 | J6: =+G6 -> 14079 | K6: =J6*0.15 -> 2111.85 | L6: =IF(J6*0.15>K6,K6,J6*0.15) -> 2111.85 | M6: =IF(K6-L6>0,K6-L6,0) -> 0 | N6: =G6*0.00759 -> 106.85961 | O6: =IF(G6*0.00759>G6,197.38,G6*0.00759) -> 106.85961 | P6: =IF(N6-O6>0,N6-O6,0) -> 0 | Q6: =+H6 -> 774.345 | R6: 0 | S6: =R6+Q6 -> 774.345 | T6: =I6-S6 -> 14079
A7: =+'Banka Lis.'!B6 -> 2 | B7: =+Puantaj!C7 -> 10264855810 | C7: =+Puantaj!D7 -> AHMET EMİRHAN | D7: =+Puantaj!E7 -> ELDEMİR | E7: =+'Banka Lis.'!H6 -> Bursa UludağÜniversitesi Üniveristesi Genel Sekreterlik Özel Kalem | F7: =+Puantaj!AK7 -> 6 | G7: =F7*1083 -> 6498 | H7: =G7*0.055 -> 357.39 | I7: =G7+H7 -> 6855.39 | J7: =+G7 -> 6498 | K7: =J7*0.15 -> 974.7 | L7: =IF(J7*0.15>K7,K7,J7*0.15) -> 974.7 | M7: =IF(K7-L7>0,K7-L7,0) -> 0 | N7: =G7*0.00759 -> 49.31982 | O7: =IF(G7*0.00759>G7,197.38,G7*0.00759) -> 49.31982 | P7: =IF(N7-O7>0,N7-O7,0) -> 0 | Q7: =+H7 -> 357.39 | R7: 0 | S7: =R7+Q7 -> 357.39 | T7: =I7-S7 -> 6498
A8: =+'Banka Lis.'!B7 -> 3 | B8: =+Puantaj!C8 -> 11230293988 | C8: =+Puantaj!D8 -> AHMET SAMED | D8: =+Puantaj!E8 -> KARABULUT | E8: =+'Banka Lis.'!H7 -> Bursa UludağÜniversitesi Üniveristesi Genel Sekreterlik Özel Kalem | F8: =+Puantaj!AK8 -> 14 | G8: =F8*1083 -> 15162 | H8: =G8*0.055 -> 833.91 | I8: =G8+H8 -> 15995.91 | J8: =+G8 -> 15162 | K8: =J8*0.15 -> 2274.3 | L8: =IF(J8*0.15>K8,K8,J8*0.15) -> 2274.3 | M8: =IF(K8-L8>0,K8-L8,0) -> 0 | N8: =G8*0.00759 -> 115.07958 | O8: =IF(G8*0.00759>G8,197.38,G8*0.00759) -> 115.07958 | P8: =IF(N8-O8>0,N8-O8,0) -> 0 | Q8: =+H8 -> 833.91 | R8: 0 | S8: =R8+Q8 -> 833.91 | T8: =I8-S8 -> 15162
A9: =+'Banka Lis.'!B8 -> 4 | B9: =+Puantaj!C9 -> 10271762804 | C9: =+Puantaj!D9 -> AHMET | D9: =+Puantaj!E9 -> ŞEN | E9: =+'Banka Lis.'!H8 -> Bursa UludağÜniversitesi Üniveristesi Genel Sekreterlik Özel Kalem | F9: =+Puantaj!AK9 -> 13 | G9: =F9*1083 -> 14079 | H9: =G9*0.055 -> 774.345 | I9: =G9+H9 -> 14853.345 | J9: =+G9 -> 14079 | K9: =J9*0.15 -> 2111.85 | L9: =IF(J9*0.15>K9,K9,J9*0.15) -> 2111.85 | M9: =IF(K9-L9>0,K9-L9,0) -> 0 | N9: =G9*0.00759 -> 106.85961 | O9: =IF(G9*0.00759>G9,197.38,G9*0.00759) -> 106.85961 | P9: =IF(N9-O9>0,N9-O9,0) -> 0 | Q9: =+H9 -> 774.345 | R9: 0 | S9: =R9+Q9 -> 774.345 | T9: =I9-S9 -> 14079
A10: =+'Banka Lis.'!B9 -> 5 | B10: =+Puantaj!C10 -> 10067475932 | C10: =+Puantaj!D10 -> AHMET YASİN | D10: =+Puantaj!E10 -> KURT | E10: =+'Banka Lis.'!H9 -> Bursa UludağÜniversitesi Üniveristesi Genel Sekreterlik Özel Kalem | F10: =+Puantaj!AK10 -> 14 | G10: =F10*1083 -> 15162 | H10: =G10*0.055 -> 833.91 | I10: =G10+H10 -> 15995.91 | J10: =+G10 -> 15162 | K10: =J10*0.15 -> 2274.3 | L10: =IF(J10*0.15>K10,K10,J10*0.15) -> 2274.3 | M10: =IF(K10-L10>0,K10-L10,0) -> 0 | N10: =G10*0.00759 -> 115.07958 | O10: =IF(G10*0.00759>G10,197.38,G10*0.00759) -> 115.07958 | P10: =IF(N10-O10>0,N10-O10,0) -> 0 | Q10: =+H10 -> 833.91 | R10: 0 | S10: =R10+Q10 -> 833.91 | T10: =I10-S10 -> 15162
A11: =+'Banka Lis.'!B10 -> 6 | B11: =+Puantaj!C11 -> 13333175444 | C11: =+Puantaj!D11 -> AKİF YAVUZ | D11: =+Puantaj!E11 -> ZENGİN | E11: =+'Banka Lis.'!H10 -> Bursa UludağÜniversitesi Üniveristesi Genel Sekreterlik Özel Kalem | F11: =+Puantaj!AK11 -> 4 | G11: =F11*1083 -> 4332 | H11: =G11*0.055 -> 238.26 | I11: =G11+H11 -> 4570.26 | J11: =+G11 -> 4332 | K11: =J11*0.15 -> 649.8 | L11: =IF(J11*0.15>K11,K11,J11*0.15) -> 649.8 | M11: =IF(K11-L11>0,K11-L11,0) -> 0 | N11: =G11*0.00759 -> 32.87988 | O11: =IF(G11*0.00759>G11,197.38,G11*0.00759) -> 32.87988 | P11: =IF(N11-O11>0,N11-O11,0) -> 0 | Q11: =+H11 -> 238.26 | R11: 0 | S11: =R11+Q11 -> 238.26 | T11: =I11-S11 -> 4332
A12: =+'Banka Lis.'!B11 -> 7 | B12: =+Puantaj!C12 -> 34411910856 | C12: =+Puantaj!D12 -> ALEYNA | D12: =+Puantaj!E12 -> ÇAKAR | E12: =+'Banka Lis.'!H11 -> Bursa UludağÜniversitesi Üniveristesi Genel Sekreterlik Özel Kalem | F12: =+Puantaj!AK12 -> 0 | G12: =F12*1083 -> 0 | H12: =G12*0.055 -> 0 | I12: =G12+H12 -> 0 | J12: =+G12 -> 0 | K12: =J12*0.15 -> 0 | L12: =IF(J12*0.15>K12,K12,J12*0.15) -> 0 | M12: =IF(K12-L12>0,K12-L12,0) -> 0 | N12: =G12*0.00759 -> 0 | O12: =IF(G12*0.00759>G12,197.38,G12*0.00759) -> 0 | P12: =IF(N12-O12>0,N12-O12,0) -> 0 | Q12: =+H12 -> 0 | R12: 0 | S12: =R12+Q12 -> 0 | T12: =I12-S12 -> 0
A13: =+'Banka Lis.'!B12 -> 8 | B13: =+Puantaj!C13 -> 11069535280 | C13: =+Puantaj!D13 -> ALİGAFFAR | D13: =+Puantaj!E13 -> AYDIN | E13: =+'Banka Lis.'!H12 -> Bursa UludağÜniversitesi Üniveristesi Genel Sekreterlik Özel Kalem | F13: =+Puantaj!AK13 -> 12 | G13: =F13*1083 -> 12996 | H13: =G13*0.055 -> 714.78 | I13: =G13+H13 -> 13710.78 | J13: =+G13 -> 12996 | K13: =J13*0.15 -> 1949.4 | L13: =IF(J13*0.15>K13,K13,J13*0.15) -> 1949.4 | M13: =IF(K13-L13>0,K13-L13,0) -> 0 | N13: =G13*0.00759 -> 98.63964 | O13: =IF(G13*0.00759>G13,197.38,G13*0.00759) -> 98.63964 | P13: =IF(N13-O13>0,N13-O13,0) -> 0 | Q13: =+H13 -> 714.78 | R13: 0 | S13: =R13+Q13 -> 714.78 | T13: =I13-S13 -> 12996
A14: =+'Banka Lis.'!B13 -> 9 | B14: =+Puantaj!C14 -> 10420954296 | C14: =+Puantaj!D14 -> ARİF | D14: =+Puantaj!E14 -> TURAN | E14: =+'Banka Lis.'!H13 -> Bursa UludağÜniversitesi Üniveristesi Genel Sekreterlik Özel Kalem | F14: =+Puantaj!AK14 -> 14 | G14: =F14*1083 -> 15162 | H14: =G14*0.055 -> 833.91 | I14: =G14+H14 -> 15995.91 | J14: =+G14 -> 15162 | K14: =J14*0.15 -> 2274.3 | L14: =IF(J14*0.15>K14,K14,J14*0.15) -> 2274.3 | M14: =IF(K14-L14>0,K14-L14,0) -> 0 | N14: =G14*0.00759 -> 115.07958 | O14: =IF(G14*0.00759>G14,197.38,G14*0.00759) -> 115.07958 | P14: =IF(N14-O14>0,N14-O14,0) -> 0 | Q14: =+H14 -> 833.91 | R14: 0 | S14: =R14+Q14 -> 833.91 | T14: =I14-S14 -> 15162
A15: =+'Banka Lis.'!B14 -> 10 | B15: =+Puantaj!C15 -> 11039638348 | C15: =+Puantaj!D15 -> ASLAN ERAY | D15: =+Puantaj!E15 -> KARAVAŞ | E15: =+'Banka Lis.'!H14 -> Bursa UludağÜniversitesi Üniveristesi Genel Sekreterlik Özel Kalem | F15: =+Puantaj!AK15 -> 15 | G15: =F15*1083 -> 16245 | H15: =G15*0.055 -> 893.475 | I15: =G15+H15 -> 17138.475 | J15: =+G15 -> 16245 | K15: =J15*0.15 -> 2436.75 | L15: =IF(J15*0.15>K15,K15,J15*0.15) -> 2436.75 | M15: =IF(K15-L15>0,K15-L15,0) -> 0 | N15: =G15*0.00759 -> 123.29955 | O15: =IF(G15*0.00759>G15,197.38,G15*0.00759) -> 123.29955 | P15: =IF(N15-O15>0,N15-O15,0) -> 0 | Q15: =+H15 -> 893.475 | R15: 0 | S15: =R15+Q15 -> 893.475 | T15: =I15-S15 -> 16245
A16: =+'Banka Lis.'!B15 -> 11 | B16: =+Puantaj!C16 -> 18397728780 | C16: =+Puantaj!D16 -> ASLI | D16: =+Puantaj!E16 -> BEKTAŞ | E16: =+'Banka Lis.'!H15 -> Bursa UludağÜniversitesi Üniveristesi Genel Sekreterlik Özel Kalem | F16: =+Puantaj!AK16 -> 5 | G16: =F16*1083 -> 5415 | H16: =G16*0.055 -> 297.825 | I16: =G16+H16 -> 5712.825 | J16: =+G16 -> 5415 | K16: =J16*0.15 -> 812.25 | L16: =IF(J16*0.15>K16,K16,J16*0.15) -> 812.25 | M16: =IF(K16-L16>0,K16-L16,0) -> 0 | N16: =G16*0.00759 -> 41.09985 | O16: =IF(G16*0.00759>G16,197.38,G16*0.00759) -> 41.09985 | P16: =IF(N16-O16>0,N16-O16,0) -> 0 | Q16: =+H16 -> 297.825 | R16: 0 | S16: =R16+Q16 -> 297.825 | T16: =I16-S16 -> 5415
A17: =+'Banka Lis.'!B16 -> 12 | B17: =+Puantaj!C17 -> 31885265086 | C17: =+Puantaj!D17 -> AYBERK | D17: =+Puantaj!E17 -> EREN | E17: =+'Banka Lis.'!H16 -> Bursa UludağÜniversitesi Üniveristesi Genel Sekreterlik Özel Kalem | F17: =+Puantaj!AK17 -> 12 | G17: =F17*1083 -> 12996 | H17: =G17*0.055 -> 714.78 | I17: =G17+H17 -> 13710.78 | J17: =+G17 -> 12996 | K17: =J17*0.15 -> 1949.4 | L17: =IF(J17*0.15>K17,K17,J17*0.15) -> 1949.4 | M17: =IF(K17-L17>0,K17-L17,0) -> 0 | N17: =G17*0.00759 -> 98.63964 | O17: =IF(G17*0.00759>G17,197.38,G17*0.00759) -> 98.63964 | P17: =IF(N17-O17>0,N17-O17,0) -> 0 | Q17: =+H17 -> 714.78 | R17: 0 | S17: =R17+Q17 -> 714.78 | T17: =I17-S17 -> 12996
... A193: =+'Banka Lis.'!B192 -> 188 | B193: =+Puantaj!C193 -> 10276740210 | C193: =+Puantaj!D193 -> ZEYNEP | D193: =+Puantaj!E193 -> DEMİRAYAK | E193: =+'Banka Lis.'!H192 -> Bursa UludağÜniversitesi Üniveristesi Genel Sekreterlik Özel Kalem | F193: =+Puantaj!AK193 -> 12 | G193: =F193*1083 -> 12996 | H193: =G193*0.055 -> 714.78 | I193: =G193+H193 -> 13710.78 | J193: =+G193 -> 12996 | K193: =J193*0.15 -> 1949.4 | L193: =IF(J193*0.15>K193,K193,J193*0.15) -> 1949.4 | M193: =IF(K193-L193>0,K193-L193,0) -> 0 | N193: =G193*0.00759 -> 98.63964 | O193: =IF(G193*0.00759>G193,197.38,G193*0.00759) -> 98.63964 | P193: =IF(N193-O193>0,N193-O193,0) -> 0 | Q193: =+H193 -> 714.78 | R193: 0 | S193: =R193+Q193 -> 714.78 | T193: =I193-S193 -> 12996
A194: =+'Banka Lis.'!B193 -> 189 | B194: =+Puantaj!C194 -> 48730397168 | C194: =+Puantaj!D194 -> MAHMUT | D194: =+Puantaj!E194 -> ÖZGAN | E194: =+'Banka Lis.'!H194 -> 0 | F194: =+Puantaj!AK194 -> 3 | G194: =F194*1083 -> 3249 | H194: =G194*0.055 -> 178.695 | I194: =G194+H194 -> 3427.695 | J194: =+G194 -> 3249 | K194: =J194*0.15 -> 487.35 | L194: =IF(J194*0.15>K194,K194,J194*0.15) -> 487.35 | M194: =IF(K194-L194>0,K194-L194,0) -> 0 | N194: =G194*0.00759 -> 24.65991 | O194: =IF(G194*0.00759>G194,197.38,G194*0.00759) -> 24.65991 | P194: =IF(N194-O194>0,N194-O194,0) -> 0 | Q194: =+H194 -> 178.695 | R194: 0 | S194: =R194+Q194 -> 178.695 | T194: =I194-S194 -> 3249
A195: GENEL TOPLAM | F195: =SUM(F6:F194) -> 2240 | G195: =SUM(G6:G194) -> 2425920 | H195: =SUM(H6:H194) -> 133425.6 | I195: =SUM(I6:I194) -> 2559345.6 | J195: =SUM(J6:J194) -> 2425920 | L195: =SUM(L6:L194) -> 363888 | M195: =SUM(M6:M194) -> 0 | P195: =SUM(P6:P194) -> 0 | Q195: =SUM(Q6:Q194) -> 133425.6 | R195: =SUM(R6:R194) -> 0 | S195: =SUM(S6:S194) -> 133425.6 | T195: =SUM(T6:T194) -> 2425920
C200: Tansu KARAKÖK | I200: Tekin ÇİMEN | P200: Mehmet AYDEMİR
C201: Şef | I201: Şube Müdürü | P201: Genel Sekreter

Sheet Banka Lis.
B1: BURSA ULUDAĞ ÜNİVERİSTESİ İŞKUR GENÇLİK PROGRAMI 13376 PORTAL NOLU KAMPÜS 1 BANKA LİSTESİ
B2: Şube Kodu | F2: Dönemi: | G2: 45992 | H2: 31.12.2025
B3: Banka Adı | E3: HALKBANK
B4: S. N. | C4: IBAN Numarası | D4: TUTAR | E4: Adı | F4: Soyadı | G4: T.C. KİMLİK NUMARASI | H4: AÇIKLAMA
B5: 1 | C5: =+Puantaj!A6 -> TR290001002151713143585001 | D5: =+BORDRO!T6 -> 14079 | E5: =+Puantaj!D6 -> ABDURRAHMAN CENGİZ | F5: =+Puantaj!E6 -> AYDOĞDU | G5: =+Puantaj!C6 -> 22985652920 | H5: Bursa UludağÜniversitesi Üniveristesi Genel Sekreterlik Özel Kalem
B6: 2 | C6: =+Puantaj!A7 -> TR270020500009943979400001 | D6: =+BORDRO!T7 -> 6498 | E6: =+Puantaj!D7 -> AHMET EMİRHAN | F6: =+Puantaj!E7 -> ELDEMİR | G6: =+Puantaj!C7 -> 10264855810 | H6: Bursa UludağÜniversitesi Üniveristesi Genel Sekreterlik Özel Kalem
B7: 3 | C7: =+Puantaj!A8 -> TR370001009010555427505003 | D7: =+BORDRO!T8 -> 15162 | E7: =+Puantaj!D8 -> AHMET SAMED | F7: =+Puantaj!E8 -> KARABULUT | G7: =+Puantaj!C8 -> 11230293988 | H7: Bursa UludağÜniversitesi Üniveristesi Genel Sekreterlik Özel Kalem
B8: 4 | C8: =+Puantaj!A9 -> TR550006701000000037357882 | D8: =+BORDRO!T9 -> 14079 | E8: =+Puantaj!D9 -> AHMET | F8: =+Puantaj!E9 -> ŞEN | G8: =+Puantaj!C9 -> 10271762804 | H8: Bursa UludağÜniversitesi Üniveristesi Genel Sekreterlik Özel Kalem
B9: 5 | C9: =+Puantaj!A10 -> TR040001009010348991905001 | D9: =+BORDRO!T10 -> 15162 | E9: =+Puantaj!D10 -> AHMET YASİN | F9: =+Puantaj!E10 -> KURT | G9: =+Puantaj!C10 -> 10067475932 | H9: Bursa UludağÜniversitesi Üniveristesi Genel Sekreterlik Özel Kalem
B10: 6 | C10: =+Puantaj!A11 -> TR070001009010961041905002 | D10: =+BORDRO!T11 -> 4332 | E10: =+Puantaj!D11 -> AKİF YAVUZ | F10: =+Puantaj!E11 -> ZENGİN | G10: =+Puantaj!C11 -> 13333175444 | H10: Bursa UludağÜniversitesi Üniveristesi Genel Sekreterlik Özel Kalem
B11: 7 | C11: =+Puantaj!A12 -> TR250001009010259614605003 | D11: =+BORDRO!T12 -> 0 | E11: =+Puantaj!D12 -> ALEYNA | F11: =+Puantaj!E12 -> ÇAKAR | G11: =+Puantaj!C12 -> 34411910856 | H11: Bursa UludağÜniversitesi Üniveristesi Genel Sekreterlik Özel Kalem
B12: 8 | C12: =+Puantaj!A13 -> TR580001009010556440305002 | D12: =+BORDRO!T13 -> 12996 | E12: =+Puantaj!D13 -> ALİGAFFAR | F12: =+Puantaj!E13 -> AYDIN | G12: =+Puantaj!C13 -> 11069535280 | H12: Bursa UludağÜniversitesi Üniveristesi Genel Sekreterlik Özel Kalem
B13: 9 | C13: =+Puantaj!A14 -> TR960001200122900001249734 | D13: =+BORDRO!T14 -> 15162 | E13: =+Puantaj!D14 -> ARİF | F13: =+Puantaj!E14 -> TURAN | G13: =+Puantaj!C14 -> 10420954296 | H13: Bursa UludağÜniversitesi Üniveristesi Genel Sekreterlik Özel Kalem
B14: 10 | C14: =+Puantaj!A15 -> TR530004600007888000653780 | D14: =+BORDRO!T15 -> 16245 | E14: =+Puantaj!D15 -> ASLAN ERAY | F14: =+Puantaj!E15 -> KARAVAŞ | G14: =+Puantaj!C15 -> 11039638348 | H14: Bursa UludağÜniversitesi Üniveristesi Genel Sekreterlik Özel Kalem
B15: 11 | C15: =+Puantaj!A16 -> TR070001009010550885705001 | D15: =+BORDRO!T16 -> 5415 | E15: =+Puantaj!D16 -> ASLI | F15: =+Puantaj!E16 -> BEKTAŞ | G15: =+Puantaj!C16 -> 18397728780 | H15: Bursa UludağÜniversitesi Üniveristesi Genel Sekreterlik Özel Kalem
B16: 12 | C16: =+Puantaj!A17 -> TR080001001914961839085005 | D16: =+BORDRO!T17 -> 12996 | E16: =+Puantaj!D17 -> AYBERK | F16: =+Puantaj!E17 -> EREN | G16: =+Puantaj!C17 -> 31885265086 | H16: Bursa UludağÜniversitesi Üniveristesi Genel Sekreterlik Özel Kalem
... B193: 189 | C193: =+Puantaj!A194 -> TR340001004002828302515004 | D193: =+BORDRO!T194 -> 3249 | E193: =+Puantaj!D194 -> MAHMUT | F193: =+Puantaj!E194 -> ÖZGAN | G193: =+Puantaj!C194 -> 48730397168 | H193: Bursa UludağÜniversitesi Üniveristesi Genel Sekreterlik Özel Kalem
B194: TOPLAM | D194: =SUM(D5:D193) -> 2425920
C196: Hazırlayan
C198: Tansu KARAKÖK | E198: Tekin ÇİMEN | H198: Mehmet AYDEMİR
C199: Şef | E199: Şube Müdürü | H199: Genel Sekreter

Sheet MUH SGK RAPORU
A1: Belgenin Mahiyeti (Asıl/Ek/İptal) | B1: Belge Türü | C1: Düzenlemeye Esas Kanun No | D1: Yeni Ünite Kodu | E1: Eski Ünite Kodu | F1: İşyeri Sıra Numarası | G1: İl Kodu | H1: Ait İşveren Numarası | I1: SSK Sicil | J1: SG NO (TC Kimlik No) | K1: Adı | L1: Soyadı | M1: Prim Ödeme Günü | N1: Uzaktan Çalışma Gün | O1: Hak Edilen Ücret | P1: Prim,İkramiye ve Bu Nitelikteki İstihkak | Q1: İşe Giriş Gün | R1: İşe Giriş Ay | S1: İşten Çıkış Gün | T1: İşten Çıkış Ay | U1: İşten Çıkış Nedeni | V1: Eksik Gün Sayısı | W1: Eksik Gün Nedeni | X1: Meslek Kodu | Y1: İstirahat Süresinde Çalışmamıştır (E/H) | Z1: Tahakkuk Nedeni | AA1: Hizmet Dönem Ay | AB1: Hizmet Dönem Yıl | AC1: Gelir Vergisinden Muaf mı? | AD1: İlgili Döneme Ait Gelir Vergisi Matrahı | AE1: Gelir Vergisi Engellilik Oranı | AF1: Hesaplanan Gelir Vergisi | AG1: Asgari Ücret İstisna Gelir Vergisi Tutarı | AH1: Gelir Vergisi Kesintisi | AI1: Asgari Ücret İstisna Damga Vergisi Tutarı | AJ1: Damga Vergisi Kesintisi
A2: A | B2: 46 | C2: 00000 | D2: 01 | E2: 01 | F2: 1494768 | G2: 016 | H2: 000 | J2: =+Puantaj!C6 -> 22985652920 | K2: =+Puantaj!D6 -> ABDURRAHMAN CENGİZ | L2: =+Puantaj!E6 -> AYDOĞDU | M2: =+BORDRO!F6 -> 13 | O2: =+BORDRO!G6 -> 14079 | P2: 0 | V2: =31-M2-Q2 -> 18 | W2: 6 | X2: 9901.04 | Y2: 2 | Z2: A | AA2: 11 | AB2: 2025 | AC2: Hayır | AD2: =+BORDRO!J6 -> 14079 | AF2: =+BORDRO!K6 -> 2111.85 | AG2: =+BORDRO!L6 -> 2111.85 | AH2: =+BORDRO!M6 -> 0 | AI2: =+BORDRO!O6 -> 106.85961 | AJ2: =+BORDRO!P6 -> 0
A3: A | B3: 46 | C3: 00000 | D3: 01 | E3: 01 | F3: 1494768 | G3: 016 | H3: 000 | J3: =+Puantaj!C7 -> 10264855810 | K3: =+Puantaj!D7 -> AHMET EMİRHAN | L3: =+Puantaj!E7 -> ELDEMİR | M3: =+BORDRO!F7 -> 6 | O3: =+BORDRO!G7 -> 6498 | P3: 0 | V3: =31-M3-Q3 -> 25 | W3: 6 | X3: 9901.04 | Y3: 2 | Z3: A | AA3: 11 | AB3: 2025 | AC3: Hayır | AD3: =+BORDRO!J7 -> 6498 | AF3: =+BORDRO!K7 -> 974.7 | AG3: =+BORDRO!L7 -> 974.7 | AH3: =+BORDRO!M7 -> 0 | AI3: =+BORDRO!O7 -> 49.31982 | AJ3: =+BORDRO!P7 -> 0
A4: A | B4: 46 | C4: 00000 | D4: 01 | E4: 01 | F4: 1494768 | G4: 016 | H4: 000 | J4: =+Puantaj!C8 -> 11230293988 | K4: =+Puantaj!D8 -> AHMET SAMED | L4: =+Puantaj!E8 -> KARABULUT | M4: =+BORDRO!F8 -> 14 | O4: =+BORDRO!G8 -> 15162 | P4: 0 | V4: =31-M4-Q4 -> 17 | W4: 6 | X4: 9901.04 | Y4: 2 | Z4: A | AA4: 11 | AB4: 2025 | AC4: Hayır | AD4: =+BORDRO!J8 -> 15162 | AF4: =+BORDRO!K8 -> 2274.3 | AG4: =+BORDRO!L8 -> 2274.3 | AH4: =+BORDRO!M8 -> 0 | AI4: =+BORDRO!O8 -> 115.07958 | AJ4: =+BORDRO!P8 -> 0
A5: A | B5: 46 | C5: 00000 | D5: 01 | E5: 01 | F5: 1494768 | G5: 016 | H5: 000 | J5: =+Puantaj!C9 -> 10271762804 | K5: =+Puantaj!D9 -> AHMET | L5: =+Puantaj!E9 -> ŞEN | M5: =+BORDRO!F9 -> 13 | O5: =+BORDRO!G9 -> 14079 | P5: 0 | V5: =31-M5-Q5 -> 18 | W5: 6 | X5: 9901.04 | Y5: 2 | Z5: A | AA5: 11 | AB5: 2025 | AC5: Hayır | AD5: =+BORDRO!J9 -> 14079 | AF5: =+BORDRO!K9 -> 2111.85 | AG5: =+BORDRO!L9 -> 2111.85 | AH5: =+BORDRO!M9 -> 0 | AI5: =+BORDRO!O9 -> 106.85961 | AJ5: =+BORDRO!P9 -> 0
A6: A | B6: 46 | C6: 00000 | D6: 01 | E6: 01 | F6: 1494768 | G6: 016 | H6: 000 | J6: =+Puantaj!C10 -> 10067475932 | K6: =+Puantaj!D10 -> AHMET YASİN | L6: =+Puantaj!E10 -> KURT | M6: =+BORDRO!F10 -> 14 | O6: =+BORDRO!G10 -> 15162 | P6: 0 | V6: =31-M6-Q6 -> 17 | W6: 6 | X6: 9901.04 | Y6: 2 | Z6: A | AA6: 11 | AB6: 2025 | AC6: Hayır | AD6: =+BORDRO!J10 -> 15162 | AF6: =+BORDRO!K10 -> 2274.3 | AG6: =+BORDRO!L10 -> 2274.3 | AH6: =+BORDRO!M10 -> 0 | AI6: =+BORDRO!O10 -> 115.07958 | AJ6: =+BORDRO!P10 -> 0
A7: A | B7: 46 | C7: 00000 | D7: 01 | E7: 01 | F7: 1494768 | G7: 016 | H7: 000 | J7: =+Puantaj!C11 -> 13333175444 | K7: =+Puantaj!D11 -> AKİF YAVUZ | L7: =+Puantaj!E11 -> ZENGİN | M7: =+BORDRO!F11 -> 4 | O7: =+BORDRO!G11 -> 4332 | P7: 0 | V7: =31-M7-Q7 -> 27 | W7: 6 | X7: 9901.04 | Y7: 2 | Z7: A | AA7: 11 | AB7: 2025 | AC7: Hayır | AD7: =+BORDRO!J11 -> 4332 | AF7: =+BORDRO!K11 -> 649.8 | AG7: =+BORDRO!L11 -> 649.8 | AH7: =+BORDRO!M11 -> 0 | AI7: =+BORDRO!O11 -> 32.87988 | AJ7: =+BORDRO!P11 -> 0
A8: A | B8: 46 | C8: 00000 | D8: 01 | E8: 01 | F8: 1494768 | G8: 016 | H8: 000 | J8: =+Puantaj!C12 -> 34411910856 | K8: =+Puantaj!D12 -> ALEYNA | L8: =+Puantaj!E12 -> ÇAKAR | M8: =+BORDRO!F12 -> 0 | O8: =+BORDRO!G12 -> 0 | P8: 0 | S8: 31 | T8: 12 | U8: 22 | V8: =31-M8-Q8 -> 31 | W8: 15 | X8: 9901.04 | Y8: 2 | Z8: A | AA8: 11 | AB8: 2025 | AC8: Hayır | AD8: =+BORDRO!J12 -> 0 | AF8: =+BORDRO!K12 -> 0 | AG8: =+BORDRO!L12 -> 0 | AH8: =+BORDRO!M12 -> 0 | AI8: =+BORDRO!O12 -> 0 | AJ8: =+BORDRO!P12 -> 0
A9: A | B9: 46 | C9: 00000 | D9: 01 | E9: 01 | F9: 1494768 | G9: 016 | H9: 000 | J9: =+Puantaj!C13 -> 11069535280 | K9: =+Puantaj!D13 -> ALİGAFFAR | L9: =+Puantaj!E13 -> AYDIN | M9: =+BORDRO!F13 -> 12 | O9: =+BORDRO!G13 -> 12996 | P9: 0 | V9: =31-M9-Q9 -> 19 | W9: 6 | X9: 9901.04 | Y9: 2 | Z9: A | AA9: 11 | AB9: 2025 | AC9: Hayır | AD9: =+BORDRO!J13 -> 12996 | AF9: =+BORDRO!K13 -> 1949.4 | AG9: =+BORDRO!L13 -> 1949.4 | AH9: =+BORDRO!M13 -> 0 | AI9: =+BORDRO!O13 -> 98.63964 | AJ9: =+BORDRO!P13 -> 0
A10: A | B10: 46 | C10: 00000 | D10: 01 | E10: 01 | F10: 1494768 | G10: 016 | H10: 000 | J10: =+Puantaj!C14 -> 10420954296 | K10: =+Puantaj!D14 -> ARİF | L10: =+Puantaj!E14 -> TURAN | M10: =+BORDRO!F14 -> 14 | O10: =+BORDRO!G14 -> 15162 | P10: 0 | V10: =31-M10-Q10 -> 17 | W10: 6 | X10: 9901.04 | Y10: 2 | Z10: A | AA10: 11 | AB10: 2025 | AC10: Hayır | AD10: =+BORDRO!J14 -> 15162 | AF10: =+BORDRO!K14 -> 2274.3 | AG10: =+BORDRO!L14 -> 2274.3 | AH10: =+BORDRO!M14 -> 0 | AI10: =+BORDRO!O14 -> 115.07958 | AJ10: =+BORDRO!P14 -> 0
A11: A | B11: 46 | C11: 00000 | D11: 01 | E11: 01 | F11: 1494768 | G11: 016 | H11: 000 | J11: =+Puantaj!C15 -> 11039638348 | K11: =+Puantaj!D15 -> ASLAN ERAY | L11: =+Puantaj!E15 -> KARAVAŞ | M11: =+BORDRO!F15 -> 15 | O11: =+BORDRO!G15 -> 16245 | P11: 0 | V11: =31-M11-Q11 -> 16 | W11: 6 | X11: 9901.04 | Y11: 2 | Z11: A | AA11: 11 | AB11: 2025 | AC11: Hayır | AD11: =+BORDRO!J15 -> 16245 | AF11: =+BORDRO!K15 -> 2436.75 | AG11: =+BORDRO!L15 -> 2436.75 | AH11: =+BORDRO!M15 -> 0 | AI11: =+BORDRO!O15 -> 123.29955 | AJ11: =+BORDRO!P15 -> 0
A12: A | B12: 46 | C12: 00000 | D12: 01 | E12: 01 | F12: 1494768 | G12: 016 | H12: 000 | J12: =+Puantaj!C16 -> 18397728780 | K12: =+Puantaj!D16 -> ASLI | L12: =+Puantaj!E16 -> BEKTAŞ | M12: =+BORDRO!F16 -> 5 | O12: =+BORDRO!G16 -> 5415 | P12: 0 | V12: =31-M12-Q12 -> 26 | W12: 6 | X12: 9901.04 | Y12: 2 | Z12: A | AA12: 11 | AB12: 2025 | AC12: Hayır | AD12: =+BORDRO!J16 -> 5415 | AF12: =+BORDRO!K16 -> 812.25 | AG12: =+BORDRO!L16 -> 812.25 | AH12: =+BORDRO!M16 -> 0 | AI12: =+BORDRO!O16 -> 41.09985 | AJ12: =+BORDRO!P16 -> 0
A13: A | B13: 46 | C13: 00000 | D13: 01 | E13: 01 | F13: 1494768 | G13: 016 | H13: 000 | J13: =+Puantaj!C17 -> 31885265086 | K13: =+Puantaj!D17 -> AYBERK | L13: =+Puantaj!E17 -> EREN | M13: =+BORDRO!F17 -> 12 | O13: =+BORDRO!G17 -> 12996 | P13: 0 | V13: =31-M13-Q13 -> 19 | W13: 6 | X13: 9901.04 | Y13: 2 | Z13: A | AA13: 11 | AB13: 2025 | AC13: Hayır | AD13: =+BORDRO!J17 -> 12996 | AF13: =+BORDRO!K17 -> 1949.4 | AG13: =+BORDRO!L17 -> 1949.4 | AH13: =+BORDRO!M17 -> 0 | AI13: =+BORDRO!O17 -> 98.63964 | AJ13: =+BORDRO!P17 -> 0
A14: A | B14: 46 | C14: 00000 | D14: 01 | E14: 01 | F14: 1494768 | G14: 016 | H14: 000 | J14: =+Puantaj!C18 -> 16364821786 | K14: =+Puantaj!D18 -> AYBERK | L14: =+Puantaj!E18 -> KILIÇ | M14: =+BORDRO!F18 -> 13 | O14: =+BORDRO!G18 -> 14079 | P14: 0 | V14: =31-M14-Q14 -> 18 | W14: 6 | X14: 9901.04 | Y14: 2 | Z14: A | AA14: 11 | AB14: 2025 | AC14: Hayır | AD14: =+BORDRO!J18 -> 14079 | AF14: =+BORDRO!K18 -> 2111.85 | AG14: =+BORDRO!L18 -> 2111.85 | AH14: =+BORDRO!M18 -> 0 | AI14: =+BORDRO!O18 -> 106.85961 | AJ14: =+BORDRO!P18 -> 0
A15: A | B15: 46 | C15: 00000 | D15: 01 | E15: 01 | F15: 1494768 | G15: 016 | H15: 000 | J15: =+Puantaj!C19 -> 10307955460 | K15: =+Puantaj!D19 -> AYÇA | L15: =+Puantaj!E19 -> YAZICI | M15: =+BORDRO!F19 -> 13 | O15: =+BORDRO!G19 -> 14079 | P15: 0 | V15: =31-M15-Q15 -> 18 | W15: 6 | X15: 9901.04 | Y15: 2 | Z15: A | AA15: 11 | AB15: 2025 | AC15: Hayır | AD15: =+BORDRO!J19 -> 14079 | AF15: =+BORDRO!K19 -> 2111.85 | AG15: =+BORDRO!L19 -> 2111.85 | AH15: =+BORDRO!M19 -> 0 | AI15: =+BORDRO!O19 -> 106.85961 | AJ15: =+BORDRO!P19 -> 0
A16: A | B16: 46 | C16: 00000 | D16: 01 | E16: 01 | F16: 1494768 | G16: 016 | H16: 000 | J16: =+Puantaj!C20 -> 37796134572 | K16: =+Puantaj!D20 -> AYŞE | L16: =+Puantaj!E20 -> KADIOĞULLARI | M16: =+BORDRO!F20 -> 13 | O16: =+BORDRO!G20 -> 14079 | P16: 0 | V16: =31-M16-Q16 -> 18 | W16: 6 | X16: 9901.04 | Y16: 2 | Z16: A | AA16: 11 | AB16: 2025 | AC16: Hayır | AD16: =+BORDRO!J20 -> 14079 | AF16: =+BORDRO!K20 -> 2111.85 | AG16: =+BORDRO!L20 -> 2111.85 | AH16: =+BORDRO!M20 -> 0 | AI16: =+BORDRO!O20 -> 106.85961 | AJ16: =+BORDRO!P20 -> 0
A17: A | B17: 46 | C17: 00000 | D17: 01 | E17: 01 | F17: 1494768 | G17: 016 | H17: 000 | J17: =+Puantaj!C21 -> 20425647000 | K17: =+Puantaj!D21 -> AYŞE | L17: =+Puantaj!E21 -> KÜÇÜKALİ | M17: =+BORDRO!F21 -> 12 | O17: =+BORDRO!G21 -> 12996 | P17: 0 | V17: =31-M17-Q17 -> 19 | W17: 6 | X17: 9901.04 | Y17: 2 | Z17: A | AA17: 11 | AB17: 2025 | AC17: Hayır | AD17: =+BORDRO!J21 -> 12996 | AF17: =+BORDRO!K21 -> 1949.4 | AG17: =+BORDRO!L21 -> 1949.4 | AH17: =+BORDRO!M21 -> 0 | AI17: =+BORDRO!O21 -> 98.63964 | AJ17: =+BORDRO!P21 -> 0
A18: A | B18: 46 | C18: 00000 | D18: 01 | E18: 01 | F18: 1494768 | G18: 016 | H18: 000 | J18: =+Puantaj!C22 -> 10211811296 | K18: =+Puantaj!D22 -> AYŞE NUR | L18: =+Puantaj!E22 -> TÜRKYILMAZ | M18: =+BORDRO!F22 -> 14 | O18: =+BORDRO!G22 -> 15162 | P18: 0 | V18: =31-M18-Q18 -> 17 | W18: 6 | X18: 9901.04 | Y18: 2 | Z18: A | AA18: 11 | AB18: 2025 | AC18: Hayır | AD18: =+BORDRO!J22 -> 15162 | AF18: =+BORDRO!K22 -> 2274.3 | AG18: =+BORDRO!L22 -> 2274.3 | AH18: =+BORDRO!M22 -> 0 | AI18: =+BORDRO!O22 -> 115.07958 | AJ18: =+BORDRO!P22 -> 0
A19: A | B19: 46 | C19: 00000 | D19: 01 | E19: 01 | F19: 1494768 | G19: 016 | H19: 000 | J19: =+Puantaj!C23 -> 38158642018 | K19: =+Puantaj!D23 -> AYŞENUR TUĞBA | L19: =+Puantaj!E23 -> KILIÇARSLAN | M19: =+BORDRO!F23 -> 13 | O19: =+BORDRO!G23 -> 14079 | P19: 0 | V19: =31-M19-Q19 -> 18 | W19: 6 | X19: 9901.04 | Y19: 2 | Z19: A | AA19: 11 | AB19: 2025 | AC19: Hayır | AD19: =+BORDRO!J23 -> 14079 | AF19: =+BORDRO!K23 -> 2111.85 | AG19: =+BORDRO!L23 -> 2111.85 | AH19: =+BORDRO!M23 -> 0 | AI19: =+BORDRO!O23 -> 106.85961 | AJ19: =+BORDRO!P23 -> 0
A20: A | B20: 46 | C20: 00000 | D20: 01 | E20: 01 | F20: 1494768 | G20: 016 | H20: 000 | J20: =+Puantaj!C24 -> 10391956060 | K20: =+Puantaj!D24 -> AYŞENUR | L20: =+Puantaj!E24 -> YILDIRIM | M20: =+BORDRO!F24 -> 14 | O20: =+BORDRO!G24 -> 15162 | P20: 0 | V20: =31-M20-Q20 -> 17 | W20: 6 | X20: 9901.04 | Y20: 2 | Z20: A | AA20: 11 | AB20: 2025 | AC20: Hayır | AD20: =+BORDRO!J24 -> 15162 | AF20: =+BORDRO!K24 -> 2274.3 | AG20: =+BORDRO!L24 -> 2274.3 | AH20: =+BORDRO!M24 -> 0 | AI20: =+BORDRO!O24 -> 115.07958 | AJ20: =+BORDRO!P24 -> 0
... A29: A | B29: 46 | C29: 00000 | D29: 01 | E29: 01 | F29: 1494768 | G29: 016 | H29: 000 | J29: =+Puantaj!C33 -> 16765732636 | K29: =+Puantaj!D33 -> BUSE | L29: =+Puantaj!E33 -> ALACA | M29: =+BORDRO!F33 -> 14 | O29: =+BORDRO!G33 -> 15162 | P29: 0 | V29: =31-M29-Q29 -> 17 | W29: 6 | X29: 9901.04 | Y29: 2 | Z29: A | AA29: 11 | AB29: 2025 | AC29: Hayır | AD29: =+BORDRO!J33 -> 15162 | AF29: =+BORDRO!K33 -> 2274.3 | AG29: =+BORDRO!L33 -> 2274.3 | AH29: =+BORDRO!M33 -> 0 | AI29: =+BORDRO!O33 -> 115.07958 | AJ29: =+BORDRO!P33 -> 0
A30: A | B30: 46 | C30: 00000 | D30: 01 | E30: 01 | F30: 1494768 | G30: 016 | H30: 000 | J30: =+Puantaj!C34 -> 10169157156 | K30: =+Puantaj!D34 -> BUSE | L30: =+Puantaj!E34 -> PAMUK | M30: =+BORDRO!F34 -> 4 | O30: =+BORDRO!G34 -> 4332 | P30: 0 | S30: 31 | T30: 12 | U30: 3 | V30: =31-M30-Q30 -> 27 | W30: 6 | X30: 9901.04 | Y30: 2 | Z30: A | AA30: 11 | AB30: 2025 | AC30: Hayır | AD30: =+BORDRO!J34 -> 4332 | AF30: =+BORDRO!K34 -> 649.8 | AG30: =+BORDRO!L34 -> 649.8 | AH30: =+BORDRO!M34 -> 0 | AI30: =+BORDRO!O34 -> 32.87988 | AJ30: =+BORDRO!P34 -> 0
A31: A | B31: 46 | C31: 00000 | D31: 01 | E31: 01 | F31: 1494768 | G31: 016 | H31: 000 | J31: =+Puantaj!C35 -> 22309168236 | K31: =+Puantaj!D35 -> CAFER | L31: =+Puantaj!E35 -> SOYLU | M31: =+BORDRO!F35 -> 14 | O31: =+BORDRO!G35 -> 15162 | P31: 0 | V31: =31-M31-Q31 -> 17 | W31: 6 | X31: 9901.04 | Y31: 2 | Z31: A | AA31: 11 | AB31: 2025 | AC31: Hayır | AD31: =+BORDRO!J35 -> 15162 | AF31: =+BORDRO!K35 -> 2274.3 | AG31: =+BORDRO!L35 -> 2274.3 | AH31: =+BORDRO!M35 -> 0 | AI31: =+BORDRO!O35 -> 115.07958 | AJ31: =+BORDRO!P35 -> 0
A32: A | B32: 46 | C32: 00000 | D32: 01 | E32: 01 | F32: 1494768 | G32: 016 | H32: 000 | J32: =+Puantaj!C36 -> 15725667650 | K32: =+Puantaj!D36 -> CANER | L32: =+Puantaj!E36 -> YILDIZ | M32: =+BORDRO!F36 -> 14 | O32: =+BORDRO!G36 -> 15162 | P32: 0 | V32: =31-M32-Q32 -> 17 | W32: 6 | X32: 9901.04 | Y32: 2 | Z32: A | AA32: 11 | AB32: 2025 | AC32: Hayır | AD32: =+BORDRO!J36 -> 15162 | AF32: =+BORDRO!K36 -> 2274.3 | AG32: =+BORDRO!L36 -> 2274.3 | AH32: =+BORDRO!M36 -> 0 | AI32: =+BORDRO!O36 -> 115.07958 | AJ32: =+BORDRO!P36 -> 0
A33: A | B33: 46 | C33: 00000 | D33: 01 | E33: 01 | F33: 1494768 | G33: 016 | H33: 000 | J33: =+Puantaj!C37 -> 15709804262 | K33: =+Puantaj!D37 -> CEMAL AFŞİN | L33: =+Puantaj!E37 -> TÜRKYILMAZ | M33: =+BORDRO!F37 -> 12 | O33: =+BORDRO!G37 -> 12996 | P33: 0 | V33: =31-M33-Q33 -> 19 | W33: 6 | X33: 9901.04 | Y33: 2 | Z33: A | AA33: 11 | AB33: 2025 | AC33: Hayır | AD33: =+BORDRO!J37 -> 12996 | AF33: =+BORDRO!K37 -> 1949.4 | AG33: =+BORDRO!L37 -> 1949.4 | AH33: =+BORDRO!M37 -> 0 | AI33: =+BORDRO!O37 -> 98.63964 | AJ33: =+BORDRO!P37 -> 0
A34: A | B34: 46 | C34: 00000 | D34: 01 | E34: 01 | F34: 1494768 | G34: 016 | H34: 000 | J34: =+Puantaj!C38 -> 10841685564 | K34: =+Puantaj!D38 -> CEMRE | L34: =+Puantaj!E38 -> GÜRŞEN | M34: =+BORDRO!F38 -> 14 | O34: =+BORDRO!G38 -> 15162 | P34: 0 | V34: =31-M34-Q34 -> 17 | W34: 6 | X34: 9901.04 | Y34: 2 | Z34: A | AA34: 11 | AB34: 2025 | AC34: Hayır | AD34: =+BORDRO!J38 -> 15162 | AF34: =+BORDRO!K38 -> 2274.3 | AG34: =+BORDRO!L38 -> 2274.3 | AH34: =+BORDRO!M38 -> 0 | AI34: =+BORDRO!O38 -> 115.07958 | AJ34: =+BORDRO!P38 -> 0
A35: A | B35: 46 | C35: 00000 | D35: 01 | E35: 01 | F35: 1494768 | G35: 016 | H35: 000 | J35: =+Puantaj!C39 -> 11102488016 | K35: =+Puantaj!D39 -> CEREN | L35: =+Puantaj!E39 -> YILDIRIM | M35: =+BORDRO!F39 -> 13 | O35: =+BORDRO!G39 -> 14079 | P35: 0 | V35: =31-M35-Q35 -> 18 | W35: 6 | X35: 9901.04 | Y35: 2 | Z35: A | AA35: 11 | AB35: 2025 | AC35: Hayır | AD35: =+BORDRO!J39 -> 14079 | AF35: =+BORDRO!K39 -> 2111.85 | AG35: =+BORDRO!L39 -> 2111.85 | AH35: =+BORDRO!M39 -> 0 | AI35: =+BORDRO!O39 -> 106.85961 | AJ35: =+BORDRO!P39 -> 0
A36: A | B36: 46 | C36: 00000 | D36: 01 | E36: 01 | F36: 1494768 | G36: 016 | H36: 000 | J36: =+Puantaj!C40 -> 45631014194 | K36: =+Puantaj!D40 -> ÇAĞLAYAN EFE | L36: =+Puantaj!E40 -> KOYUNCU | M36: =+BORDRO!F40 -> 12 | O36: =+BORDRO!G40 -> 12996 | P36: 0 | V36: =31-M36-Q36 -> 19 | W36: 6 | X36: 9901.04 | Y36: 2 | Z36: A | AA36: 11 | AB36: 2025 | AC36: Hayır | AD36: =+BORDRO!J40 -> 12996 | AF36: =+BORDRO!K40 -> 1949.4 | AG36: =+BORDRO!L40 -> 1949.4 | AH36: =+BORDRO!M40 -> 0 | AI36: =+BORDRO!O40 -> 98.63964 | AJ36: =+BORDRO!P40 -> 0
A37: A | B37: 46 | C37: 00000 | D37: 01 | E37: 01 | F37: 1494768 | G37: 016 | H37: 000 | J37: =+Puantaj!C41 -> 64426278672 | K37: =+Puantaj!D41 -> DİCLE | L37: =+Puantaj!E41 -> GEYİK | M37: =+BORDRO!F41 -> 13 | O37: =+BORDRO!G41 -> 14079 | P37: 0 | V37: =31-M37-Q37 -> 18 | W37: 6 | X37: 9901.04 | Y37: 2 | Z37: A | AA37: 11 | AB37: 2025 | AC37: Hayır | AD37: =+BORDRO!J41 -> 14079 | AF37: =+BORDRO!K41 -> 2111.85 | AG37: =+BORDRO!L41 -> 2111.85 | AH37: =+BORDRO!M41 -> 0 | AI37: =+BORDRO!O41 -> 106.85961 | AJ37: =+BORDRO!P41 -> 0
A38: A | B38: 46 | C38: 00000 | D38: 01 | E38: 01 | F38: 1494768 | G38: 016 | H38: 000 | J38: =+Puantaj!C42 -> 11158958198 | K38: =+Puantaj!D42 -> ECEM | L38: =+Puantaj!E42 -> BULUT | M38: =+BORDRO!F42 -> 13 | O38: =+BORDRO!G42 -> 14079 | P38: 0 | V38: =31-M38-Q38 -> 18 | W38: 6 | X38: 9901.04 | Y38: 2 | Z38: A | AA38: 11 | AB38: 2025 | AC38: Hayır | AD38: =+BORDRO!J42 -> 14079 | AF38: =+BORDRO!K42 -> 2111.85 | AG38: =+BORDRO!L42 -> 2111.85 | AH38: =+BORDRO!M42 -> 0 | AI38: =+BORDRO!O42 -> 106.85961 | AJ38: =+BORDRO!P42 -> 0
A39: A | B39: 46 | C39: 00000 | D39: 01 | E39: 01 | F39: 1494768 | G39: 016 | H39: 000 | J39: =+Puantaj!C43 -> 10438965994 | K39: =+Puantaj!D43 -> EFE | L39: =+Puantaj!E43 -> FEVZİOĞLU | M39: =+BORDRO!F43 -> 14 | O39: =+BORDRO!G43 -> 15162 | P39: 0 | V39: =31-M39-Q39 -> 17 | W39: 6 | X39: 9901.04 | Y39: 2 | Z39: A | AA39: 11 | AB39: 2025 | AC39: Hayır | AD39: =+BORDRO!J43 -> 15162 | AF39: =+BORDRO!K43 -> 2274.3 | AG39: =+BORDRO!L43 -> 2274.3 | AH39: =+BORDRO!M43 -> 0 | AI39: =+BORDRO!O43 -> 115.07958 | AJ39: =+BORDRO!P43 -> 0
A40: A | B40: 46 | C40: 00000 | D40: 01 | E40: 01 | F40: 1494768 | G40: 016 | H40: 000 | J40: =+Puantaj!C44 -> 10634557832 | K40: =+Puantaj!D44 -> EFE | L40: =+Puantaj!E44 -> ŞAHİN | M40: =+BORDRO!F44 -> 14 | O40: =+BORDRO!G44 -> 15162 | P40: 0 | V40: =31-M40-Q40 -> 17 | W40: 6 | X40: 9901.04 | Y40: 2 | Z40: A | AA40: 11 | AB40: 2025 | AC40: Hayır | AD40: =+BORDRO!J44 -> 15162 | AF40: =+BORDRO!K44 -> 2274.3 | AG40: =+BORDRO!L44 -> 2274.3 | AH40: =+BORDRO!M44 -> 0 | AI40: =+BORDRO!O44 -> 115.07958 | AJ40: =+BORDRO!P44 -> 0
A41: A | B41: 46 | C41: 00000 | D41: 01 | E41: 01 | F41: 1494768 | G41: 016 | H41: 000 | J41: =+Puantaj!C45 -> 10257029938 | K41: =+Puantaj!D45 -> EGEMEN | L41: =+Puantaj!E45 -> KÜÇÜKLER | M41: =+BORDRO!F45 -> 8 | O41: =+BORDRO!G45 -> 8664 | P41: 0 | V41: =31-M41-Q41 -> 23 | W41: 6 | X41: 9901.04 | Y41: 2 | Z41: A | AA41: 11 | AB41: 2025 | AC41: Hayır | AD41: =+BORDRO!J45 -> 8664 | AF41: =+BORDRO!K45 -> 1299.6 | AG41: =+BORDRO!L45 -> 1299.6 | AH41: =+BORDRO!M45 -> 0 | AI41: =+BORDRO!O45 -> 65.75976 | AJ41: =+BORDRO!P45 -> 0
A42: A | B42: 46 | C42: 00000 | D42: 01 | E42: 01 | F42: 1494768 | G42: 016 | H42: 000 | J42: =+Puantaj!C46 -> 10067993948 | K42: =+Puantaj!D46 -> EKREM | L42: =+Puantaj!E46 -> TERZİOĞLU | M42: =+BORDRO!F46 -> 12 | O42: =+BORDRO!G46 -> 12996 | P42: 0 | V42: =31-M42-Q42 -> 19 | W42: 6 | X42: 9901.04 | Y42: 2 | Z42: A | AA42: 11 | AB42: 2025 | AC42: Hayır | AD42: =+BORDRO!J46 -> 12996 | AF42: =+BORDRO!K46 -> 1949.4 | AG42: =+BORDRO!L46 -> 1949.4 | AH42: =+BORDRO!M46 -> 0 | AI42: =+BORDRO!O46 -> 98.63964 | AJ42: =+BORDRO!P46 -> 0
... A61: A | B61: 46 | C61: 00000 | D61: 01 | E61: 01 | F61: 1494768 | G61: 016 | H61: 000 | J61: =+Puantaj!C65 -> 10267937780 | K61: =+Puantaj!D65 -> ENNUR | L61: =+Puantaj!E65 -> ÜNAL | M61: =+BORDRO!F65 -> 14 | O61: =+BORDRO!G65 -> 15162 | P61: 0 | V61: =31-M61-Q61 -> 17 | W61: 6 | X61: 9901.04 | Y61: 2 | Z61: A | AA61: 11 | AB61: 2025 | AC61: Hayır | AD61: =+BORDRO!J65 -> 15162 | AF61: =+BORDRO!K65 -> 2274.3 | AG61: =+BORDRO!L65 -> 2274.3 | AH61: =+BORDRO!M65 -> 0 | AI61: =+BORDRO!O65 -> 115.07958 | AJ61: =+BORDRO!P65 -> 0
A62: A | B62: 46 | C62: 00000 | D62: 01 | E62: 01 | F62: 1494768 | G62: 016 | H62: 000 | J62: =+Puantaj!C66 -> 10559226820 | K62: =+Puantaj!D66 -> EREN | L62: =+Puantaj!E66 -> BEYDİLLİ | M62: =+BORDRO!F66 -> 0 | O62: =+BORDRO!G66 -> 0 | P62: 0 | S62: 12 | T62: 12 | U62: 22 | V62: 12 | W62: 15 | X62: 9901.04 | Y62: 2 | Z62: A | AA62: 11 | AB62: 2025 | AC62: Hayır | AD62: =+BORDRO!J66 -> 0 | AF62: =+BORDRO!K66 -> 0 | AG62: =+BORDRO!L66 -> 0 | AH62: =+BORDRO!M66 -> 0 | AI62: =+BORDRO!O66 -> 0 | AJ62: =+BORDRO!P66 -> 0
A63: A | B63: 46 | C63: 00000 | D63: 01 | E63: 01 | F63: 1494768 | G63: 016 | H63: 000 | J63: =+Puantaj!C67 -> 10129854538 | K63: =+Puantaj!D67 -> EREN | L63: =+Puantaj!E67 -> BOYLU | M63: =+BORDRO!F67 -> 13 | O63: =+BORDRO!G67 -> 14079 | P63: 0 | V63: =31-M63-Q63 -> 18 | W63: 6 | X63: 9901.04 | Y63: 2 | Z63: A | AA63: 11 | AB63: 2025 | AC63: Hayır | AD63: =+BORDRO!J67 -> 14079 | AF63: =+BORDRO!K67 -> 2111.85 | AG63: =+BORDRO!L67 -> 2111.85 | AH63: =+BORDRO!M67 -> 0 | AI63: =+BORDRO!O67 -> 106.85961 | AJ63: =+BORDRO!P67 -> 0
A64: A | B64: 46 | C64: 00000 | D64: 01 | E64: 01 | F64: 1494768 | G64: 016 | H64: 000 | J64: =+Puantaj!C68 -> 10591948872 | K64: =+Puantaj!D68 -> EREN | L64: =+Puantaj!E68 -> SAĞIR | M64: =+BORDRO!F68 -> 14 | O64: =+BORDRO!G68 -> 15162 | P64: 0 | V64: =31-M64-Q64 -> 17 | W64: 6 | X64: 9901.04 | Y64: 2 | Z64: A | AA64: 11 | AB64: 2025 | AC64: Hayır | AD64: =+BORDRO!J68 -> 15162 | AF64: =+BORDRO!K68 -> 2274.3 | AG64: =+BORDRO!L68 -> 2274.3 | AH64: =+BORDRO!M68 -> 0 | AI64: =+BORDRO!O68 -> 115.07958 | AJ64: =+BORDRO!P68 -> 0
A65: A | B65: 46 | C65: 00000 | D65: 01 | E65: 01 | F65: 1494768 | G65: 016 | H65: 000 | J65: =+Puantaj!C69 -> 31750012616 | K65: =+Puantaj!D69 -> ERTUĞRUL | L65: =+Puantaj!E69 -> YILDIRAN | M65: =+BORDRO!F69 -> 14 | O65: =+BORDRO!G69 -> 15162 | P65: 0 | V65: =31-M65-Q65 -> 17 | W65: 6 | X65: 9901.04 | Y65: 2 | Z65: A | AA65: 11 | AB65: 2025 | AC65: Hayır | AD65: =+BORDRO!J69 -> 15162 | AF65: =+BORDRO!K69 -> 2274.3 | AG65: =+BORDRO!L69 -> 2274.3 | AH65: =+BORDRO!M69 -> 0 | AI65: =+BORDRO!O69 -> 115.07958 | AJ65: =+BORDRO!P69 -> 0
A66: A | B66: 46 | C66: 00000 | D66: 01 | E66: 01 | F66: 1494768 | G66: 016 | H66: 000 | J66: =+Puantaj!C70 -> 11758988366 | K66: =+Puantaj!D70 -> ESRA BENAN | L66: =+Puantaj!E70 -> ÇETİN | M66: =+BORDRO!F70 -> 13 | O66: =+BORDRO!G70 -> 14079 | P66: 0 | V66: =31-M66-Q66 -> 18 | W66: 6 | X66: 9901.04 | Y66: 2 | Z66: A | AA66: 11 | AB66: 2025 | AC66: Hayır | AD66: =+BORDRO!J70 -> 14079 | AF66: =+BORDRO!K70 -> 2111.85 | AG66: =+BORDRO!L70 -> 2111.85 | AH66: =+BORDRO!M70 -> 0 | AI66: =+BORDRO!O70 -> 106.85961 | AJ66: =+BORDRO!P70 -> 0
...

Sheet HALKBANK
A1: Ödeme/Kesinti Tarihi (YYYYAAGG)
A2: Firma Müşteri No
A3: Firma Şube Kodu* | C3: 1329
A4: Firma Hesap No / IBAN | C4: TR040001200132900004000258
A5: Dosya Açıklaması | C5: Genel Sekreterlik Özel kalem
A6: Ödeme/Kesinti (Lütfen Seçiniz) | C6: Ödeme
A7: Ödeme Türü (Lütfen Seçiniz) | E7: Ödeme/Kesinti Yapılacak
A8: Ödeme Açıklama (Ödeme Türü Diğer ise) | C8: İŞKUR Gençlik Programı Katılımcı | E8: Toplam Tutar | F8: =SUM(C13:C201) -> 2425920
A9: Ödeme Dönemi | C9: 2025 Kasım Ayı 13376 Kampüs 1 | E9: Toplam Personel | F9: 186
A10: *: Hesap No kullanılacak ise zorunludur. IBAN kullanımında yazılmamalıdır.
A12: Personel Şube* | B12: Personel Hesap No / IBAN | C12: Tutar | D12: TCKN | E12: Personel Adı | F12: Soyadı
A13: 1329 | B13: ='Banka Lis.'!C5 -> TR290001002151713143585001 | C13: ='Banka Lis.'!D5 -> 14079 | D13: ='Banka Lis.'!G5 -> 22985652920 | E13: ='Banka Lis.'!E5 -> ABDURRAHMAN CENGİZ | F13: ='Banka Lis.'!F5 -> AYDOĞDU
A14: 1329 | B14: ='Banka Lis.'!C6 -> TR270020500009943979400001 | C14: ='Banka Lis.'!D6 -> 6498 | D14: ='Banka Lis.'!G6 -> 10264855810 | E14: ='Banka Lis.'!E6 -> AHMET EMİRHAN | F14: ='Banka Lis.'!F6 -> ELDEMİR
A15: 1329 | B15: ='Banka Lis.'!C7 -> TR370001009010555427505003 | C15: ='Banka Lis.'!D7 -> 15162 | D15: ='Banka Lis.'!G7 -> 11230293988 | E15: ='Banka Lis.'!E7 -> AHMET SAMED | F15: ='Banka Lis.'!F7 -> KARABULUT
A16: 1329 | B16: ='Banka Lis.'!C8 -> TR550006701000000037357882 | C16: ='Banka Lis.'!D8 -> 14079 | D16: ='Banka Lis.'!G8 -> 10271762804 | E16: ='Banka Lis.'!E8 -> AHMET | F16: ='Banka Lis.'!F8 -> ŞEN
A17: 1329 | B17: ='Banka Lis.'!C9 -> TR040001009010348991905001 | C17: ='Banka Lis.'!D9 -> 15162 | D17: ='Banka Lis.'!G9 -> 10067475932 | E17: ='Banka Lis.'!E9 -> AHMET YASİN | F17: ='Banka Lis.'!F9 -> KURT
A18: 1329 | B18: ='Banka Lis.'!C10 -> TR070001009010961041905002 | C18: ='Banka Lis.'!D10 -> 4332 | D18: ='Banka Lis.'!G10 -> 13333175444 | E18: ='Banka Lis.'!E10 -> AKİF YAVUZ | F18: ='Banka Lis.'!F10 -> ZENGİN
A19: 1329 | B19: ='Banka Lis.'!C11 -> TR250001009010259614605003 | C19: ='Banka Lis.'!D11 -> 0 | D19: ='Banka Lis.'!G11 -> 34411910856 | E19: ='Banka Lis.'!E11 -> ALEYNA | F19: ='Banka Lis.'!F11 -> ÇAKAR
A20: 1329 | B20: ='Banka Lis.'!C12 -> TR580001009010556440305002 | C20: ='Banka Lis.'!D12 -> 12996 | D20: ='Banka Lis.'!G12 -> 11069535280 | E20: ='Banka Lis.'!E12 -> ALİGAFFAR | F20: ='Banka Lis.'!F12 -> AYDIN
A21: 1329 | B21: ='Banka Lis.'!C13 -> TR960001200122900001249734 | C21: ='Banka Lis.'!D13 -> 15162 | D21: ='Banka Lis.'!G13 -> 10420954296 | E21: ='Banka Lis.'!E13 -> ARİF | F21: ='Banka Lis.'!F13 -> TURAN
A22: 1329 | B22: ='Banka Lis.'!C14 -> TR530004600007888000653780 | C22: ='Banka Lis.'!D14 -> 16245 | D22: ='Banka Lis.'!G14 -> 11039638348 | E22: ='Banka Lis.'!E14 -> ASLAN ERAY | F22: ='Banka Lis.'!F14 -> KARAVAŞ
A23: 1329 | B23: ='Banka Lis.'!C15 -> TR070001009010550885705001 | C23: ='Banka Lis.'!D15 -> 5415 | D23: ='Banka Lis.'!G15 -> 18397728780 | E23: ='Banka Lis.'!E15 -> ASLI | F23: ='Banka Lis.'!F15 -> BEKTAŞ
A24: 1329 | B24: ='Banka Lis.'!C16 -> TR080001001914961839085005 | C24: ='Banka Lis.'!D16 -> 12996 | D24: ='Banka Lis.'!G16 -> 31885265086 | E24: ='Banka Lis.'!E16 -> AYBERK | F24: ='Banka Lis.'!F16 -> EREN
... A201: 1329 | B201: ='Banka Lis.'!C193 -> TR340001004002828302515004 | C201: ='Banka Lis.'!D193 -> 3249 | D201: ='Banka Lis.'!G193 -> 48730397168 | E201: ='Banka Lis.'!E193 -> MAHMUT | F201: ='Banka Lis.'!F193 -> ÖZGAN
A203: ='Banka Lis.'!C196 -> Hazırlayan
A205: ='Banka Lis.'!C198 -> Tansu KARAKÖK | B205: ='Banka Lis.'!E198 -> Tekin ÇİMEN | E205: Mehmet AYDEMİR
A206: ='Banka Lis.'!C199 -> Şef | B206: ='Banka Lis.'!E199 -> Şube Müdürü | E206: Genel Sekreter
